Workbook

Sheet Cấu thành pod
A1: CẤU THÀNH POD – INDOOR POD V3
A2: Kích thước ghi theo Rộng (trái–phải) × Sâu (trước–sau) × Cao, đơn vị mm.
A4: A. THÔNG SỐ TỔNG
A5: Hạng mục | C5: Giá trị | F5: Ghi chú
A6: Kích thước ngoài (R × S × C) | C6: 2500 × 1700 × 2417 | F6: Cao tính cả chân tăng chỉnh; jack nguồn mặt sau nhô thêm ≈18 mm
A7: Kích thước lọt lòng (R × S × C) | C7: 2372 × 1480 × 2223 | F7: Từ mặt ván ốp trong đến mặt kính cửa; cao từ mặt sàn đến trần
A8: Diện tích sàn trong | C8: ≈ 3.5 m²
A9: Cửa | C9: 1 cánh kính, 1176 × 2011 | F9: Cửa mở quay, 3 bản lề + 1 tay nắm
A10: Mặt trước | C10: Kính xám khói + decor khung thép ốp nhôm vàng | F10: Gồm cửa, vách kính cố định và 3 cụm decor (trái, phải, trên)
A11: Mặt ngoài vách / nóc | C11: Tấm nhôm 2 mm màu vàng
A12: Thông gió | C12: 2 cụm quạt trên nóc (4 quạt) | F12: Trần trong có lưới lỗ thông gió dưới quạt
A13: Chiếu sáng | C13: 2 đèn ốp trần vuông 170 × 170
A14: Điện / mạng | C14: Mặt trong: công tắc, ổ cắm, ổ LAN · Mặt ngoài: jack nguồn, jack LAN | F14: Đặt ở vách sau giữa
A15: Nội thất | C15: 1 bàn 600 × 1000, cao 820 | F15: Đặt sát vách sau giữa
A16: Chân đế | C16: 6 chân tăng chỉnh D50 ren M12 | F16: Bắt dưới khung sàn thép
A17: Cụm lớn nhất khi vận chuyển | C17: Trần: 2480 × 1486 × 64 | F17: Vách bên: 64 × 1496 × 2300
A19: B. CÁC CỤM CẤU THÀNH
A20: STT | B20: Cụm | C20: Mã | D20: SL | E20: Kích thước bao (R × S × C) | F20: Vật liệu chính | G20: Cấu tạo / thành phần | H20: Liên kết khi lắp
A21: KẾT CẤU CHÍNH
A22: 1 | B22: Khung sàn | C22: FL | D22: 1 | E22: 2500 × 1703 × 106 | F22: Thép hộp | G22: Hộp thép 100x50, 60x30, 20x20, pát bẻ góc, nẹp nhôm ngưỡng cửa | H22: Đặt trên 6 chân tăng chỉnh
A23: 2 | B23: Chân tăng chỉnh | C23: MUA | D23: 6 | E23: Ø50, cao 81 | F23: Thép | G23: Chân tăng chỉnh D50 ren M12 | H23: Vặn vào lỗ ren dưới khung sàn
A24: 3 | B24: Sàn | C24: FLR | D24: 1 (2 tấm) | E24: 2370 × 1429 | F24: Gỗ | G24: 2 tấm ván gỗ 9 mm | H24: Lát trên khung sàn
A25: 4 | B25: Vách trái | C25: LW | D25: 1 | E25: 64 × 1496 × 2300 | F25: Gỗ + nhôm | G25: Khung gỗ 40x40 · ván gỗ ốp trong 9 mm · ván gỗ 6 mm · tấm nhôm 2 mm vàng mặt ngoài | H25: Vách sau trái: 4 vít M8x60 · Trần: 3 vít M8x60
A26: 5 | B26: Vách phải | C26: RW | D26: 1 | E26: 64 × 1496 × 2300 | F26: Gỗ + nhôm | G26: Khung gỗ 40x40 · ván gỗ ốp trong 9 mm · ván gỗ 6 mm · tấm nhôm 2 mm vàng mặt ngoài | H26: Vách sau phải: 4 vít M8x60 · Trần: 3 vít M8x60
A27: 6 | B27: Vách sau – trái | C27: BWL | D27: 1 | E27: 939 × 64 × 2300 | F27: Gỗ + nhôm | G27: Khung gỗ 40x40 · ván gỗ ốp trong 9 mm · ván gỗ 6 mm · tấm nhôm 2 mm vàng mặt ngoài | H27: Vách trái: 4 vít M8x60 · Vách sau giữa: 4 vít M8x40 · Trần: 2 vít M8x60
A28: 7 | B28: Vách sau – giữa | C28: BWC | D28: 1 | E28: 640 × 64 × 2300 | F28: Gỗ + nhôm | G28: Khung gỗ 40x40 · ván gỗ ốp trong 9 mm · ván gỗ 6 mm · tấm nhôm 2 mm vàng mặt ngoài · tấm nhôm vàng ốp trang trí mặt trong · lỗ đi dây, cụm điện | H28: Vách sau trái/phải: 8 vít M8x40
A29: 8 | B29: Vách sau – phải | C29: BWR | D29: 1 | E29: 939 × 64 × 2300 | F29: Gỗ + nhôm | G29: Khung gỗ 40x40 · ván gỗ ốp trong 9 mm · ván gỗ 6 mm · tấm nhôm 2 mm vàng mặt ngoài | H29: Vách phải: 4 vít M8x60 · Vách sau giữa: 4 vít M8x40 · Trần: 2 vít M8x60
A30: 9 | B30: Trần | C30: CL | D30: 1 | E30: 2480 × 1486 × 64 | F30: Gỗ + nhôm | G30: Khung gỗ 40x40 · ván gỗ ốp trong 9 mm (có lưới lỗ thông gió) · ván gỗ 6 mm · tấm nhôm 2 mm vàng | H30: Bắt xuống 4 vách: 10 vít M8x60
A31: MẶT TRƯỚC
A32: 10 | B32: Decor trái | C32: DL | D32: 1 | E32: 278 × 230 × 2301 | F32: Thép + nhôm | G32: Khung hộp thép 16x16, 60x20 · ốp nhôm 3 mm vàng
A33: 11 | B33: Decor phải | C33: DR | D33: 1 | E33: 1020 × 235 × 2302 | F33: Thép + nhôm | G33: Khung hộp thép 16x16 · ốp nhôm 3 mm vàng (có tấm uốn định hình)
A34: 12 | B34: Decor trên | C34: DT | D34: 1 | E34: 1697 × 235 × 280 | F34: Thép + nhôm | G34: Khung hộp thép 16x16 · ốp nhôm 3 mm vàng
A35: 13 | B35: Cửa kính | C35: GL | D35: 1 | E35: 1176 × 10 × 2011 | F35: Kính | G35: Kính xám khói 10 mm | H35: 3 bản lề kính + 1 tay nắm 300 mm
A36: 14 | B36: Vách kính cố định | C36: GW | D36: 1 | E36: 1014 × 10 × 2017 | F36: Kính | G36: Kính xám khói 10 mm, cạnh vát theo decor
A37: THIẾT BỊ & NỘI THẤT
A38: 15 | B38: Quạt thông gió | C38: MUA | D38: 2 cụm (4 quạt) | E38: 202 × 404 × 60 / cụm | F38: Linh kiện | G38: Mỗi cụm 2 quạt ~200 × 200 | H38: Lắp trên nóc
A39: 16 | B39: Đèn ốp trần | C39: MUA | D39: 2 | E39: 170 × 170 × 25 | F39: Linh kiện | G39: Đèn vuông | H39: Lắp dưới trần
A40: 17 | B40: Công tắc · ổ cắm · ổ LAN | C40: MUA | D40: 1 mỗi loại | E40: 86 × 86 | F40: Linh kiện | G40: Mặt trong vách sau giữa
A41: 18 | B41: Jack nguồn · jack LAN | C41: MUA | D41: 1 mỗi loại | E41: ≈ 35 × 35 | F41: Linh kiện | G41: Mặt ngoài vách sau giữa
A42: 19 | B42: Bàn | C42: TB | D42: 1 | E42: 600 × 1000 × 820 | F42: Gỗ + thép | G42: Mặt gỗ 20 mm · chân ống thép Ø100 · đế thép 200 × 200 | H42: Đặt trên sàn, sát vách sau giữa

Sheet BOM
A1: BOM VẬT TƯ – INDOOR POD V3
A2: Kích thước tổng: 2500 × 1718 × 2417 mm · Cập nhật 29/10/2026
A4: STT | B4: Mã | C4: Hạng mục | D4: Vật liệu | E4: Quy cách | F4: Dài (mm) | G4: Rộng (mm) | H4: Dày (mm) | I4: Số lượng | J4: Tổng dài (m) | K4: Diện tích (m²) | L4: Ghi chú
A5: FL — Khung sàn
A6: 1 | B6: FL-01 | C6: Khung sàn | D6: Thép | E6: Hộp thép 100x50 | F6: 2400 | G6: 100 | H6: 50 | I6: 1 | J6: =F6*I6/1000 -> 2.4
A7: 2 | B7: FL-02 | C7: Khung sàn | D7: Thép | E7: Hộp thép 100x50 | F7: 2020 | G7: 100 | H7: 50 | I7: 1 | J7: =F7*I7/1000 -> 2.02
A8: 3 | B8: FL-03 | C8: Khung sàn | D8: Thép | E8: Hộp thép 100x50 | F8: 1370 | G8: 100 | H8: 50 | I8: 2 | J8: =F8*I8/1000 -> 2.74
A9: 4 | B9: FL-04 | C9: Khung sàn | D9: Thép | E9: Hộp thép 100x50 | F9: 269 | G9: 100 | H9: 50 | I9: 1 | J9: =F9*I9/1000 -> 0.269
A10: 5 | B10: FL-05 | C10: Khung sàn | D10: Thép | E10: Hộp thép 100x50 | F10: 212 | G10: 100 | H10: 50 | I10: 1 | J10: =F10*I10/1000 -> 0.212
A11: 6 | B11: FL-06 | C11: Khung sàn | D11: Thép | E11: Hộp thép 100x50 | F11: 150 | G11: 100 | H11: 50 | I11: 2 | J11: =F11*I11/1000 -> 0.3
A12: 7 | B12: FL-07 | C12: Khung sàn | D12: Thép | E12: Hộp thép 100x50 | F12: 123.5 | G12: 100 | H12: 50 | I12: 1 | J12: =F12*I12/1000 -> 0.1235
A13: 8 | B13: FL-08 | C13: Khung sàn | D13: Thép | E13: Hộp thép 100x50 | F13: 76 | G13: 100 | H13: 50 | I13: 4 | J13: =F13*I13/1000 -> 0.304 | L13: Đoạn ngắn cắt xiên, dài ≈76 mm
A14: 9 | B14: FL-09 | C14: Khung sàn | D14: Thép | E14: Hộp thép 20x20 | F14: 137.5 | G14: 20 | H14: 20 | I14: 5 | J14: =F14*I14/1000 -> 0.6875
A15: 10 | B15: FL-10 | C15: Khung sàn | D15: Thép | E15: Hộp thép 60x30 | F15: 2400 | G15: 60 | H15: 30 | I15: 3 | J15: =F15*I15/1000 -> 7.2
A16: 11 | B16: FL-11 | C16: Ốp mép sàn trước | D16: Nhôm | E16: Tấm nhôm 3 mm màu vàng | F16: 1917 | G16: 204 | H16: 3 | I16: 1 | K16: =F16*G16*I16/1000000 -> 0.391068 | L16: Nẹp ngưỡng cửa
A17: 12 | B17: FL-12 | C17: Pát | D17: Thép | E17: Bản mã thép 3 mm | F17: 40 | G17: 30 | H17: 4 | I17: 1
A18: 13 | B18: FL-13 | C18: Pát | D18: Thép | E18: Pát thép bẻ góc 3 mm | F18: 60 | G18: 50 | H18: 36 | I18: 4
A19: FLR — Sàn
A20: 14 | B20: FLR-01 | C20: Sàn | D20: Gỗ | E20: Ván gỗ 9 mm | F20: 1429 | G20: 1184.5 | H20: 9 | I20: 2 | K20: =F20*G20*I20/1000000 -> 3.385301
A21: LW — Vách trái
A22: 15 | B22: LW-01 | C22: Khung | D22: Gỗ | E22: Thanh gỗ 40x40 | F22: 2169 | G22: 40 | H22: 40 | I22: 2 | J22: =F22*I22/1000 -> 4.338
A23: 16 | B23: LW-02 | C23: Khung | D23: Gỗ | E23: Thanh gỗ 40x40 | F23: 1447 | G23: 40 | H23: 40 | I23: 2 | J23: =F23*I23/1000 -> 2.894
A24: 17 | B24: LW-03 | C24: Khung | D24: Gỗ | E24: Thanh gỗ 40x40 | F24: 1367 | G24: 40 | H24: 40 | I24: 1 | J24: =F24*I24/1000 -> 1.367
A25: 18 | B25: LW-04 | C25: Ốp trong | D25: Gỗ | E25: Ván gỗ 9 mm | F25: 2234 | G25: 715 | H25: 9 | I25: 2 | K25: =F25*G25*I25/1000000 -> 3.19462
A26: 19 | B26: LW-05 | C26: Ốp ngoài (lớp gỗ) | D26: Gỗ | E26: Ván gỗ 6 mm | F26: 2300 | G26: 276 | H26: 6 | I26: 1 | K26: =F26*G26*I26/1000000 -> 0.6348 | L26: Lớp gỗ dưới tấm nhôm
A27: 20 | B27: LW-06 | C27: Ốp ngoài (lớp gỗ) | D27: Gỗ | E27: Ván gỗ 6 mm | F27: 2300 | G27: 1220 | H27: 6 | I27: 1 | K27: =F27*G27*I27/1000000 -> 2.806 | L27: Lớp gỗ dưới tấm nhôm
A28: 21 | B28: LW-07 | C28: Ốp ngoài cùng | D28: Nhôm | E28: Tấm nhôm 2 mm màu vàng | F28: 2300 | G28: 276 | H28: 2 | I28: 1 | K28: =F28*G28*I28/1000000 -> 0.6348 | L28: Mặt ngoài pod
A29: 22 | B29: LW-08 | C29: Ốp ngoài cùng | D29: Nhôm | E29: Tấm nhôm 2 mm màu vàng | F29: 2300 | G29: 1220 | H29: 2 | I29: 1 | K29: =F29*G29*I29/1000000 -> 2.806 | L29: Mặt ngoài pod
A30: RW — Vách phải
A31: 23 | B31: RW-01 | C31: Khung | D31: Gỗ | E31: Thanh gỗ 40x40 | F31: 2169 | G31: 40 | H31: 40 | I31: 2 | J31: =F31*I31/1000 -> 4.338
A32: 24 | B32: RW-02 | C32: Khung | D32: Gỗ | E32: Thanh gỗ 40x40 | F32: 1447 | G32: 40 | H32: 40 | I32: 2 | J32: =F32*I32/1000 -> 2.894
A33: 25 | B33: RW-03 | C33: Khung | D33: Gỗ | E33: Thanh gỗ 40x40 | F33: 1367 | G33: 40 | H33: 40 | I33: 1 | J33: =F33*I33/1000 -> 1.367
A34: 26 | B34: RW-04 | C34: Ốp trong | D34: Gỗ | E34: Ván gỗ 9 mm | F34: 2234 | G34: 715 | H34: 9 | I34: 2 | K34: =F34*G34*I34/1000000 -> 3.19462
A35: 27 | B35: RW-05 | C35: Ốp ngoài (lớp gỗ) | D35: Gỗ | E35: Ván gỗ 6 mm | F35: 2300 | G35: 1220 | H35: 6 | I35: 1 | K35: =F35*G35*I35/1000000 -> 2.806 | L35: Lớp gỗ dưới tấm nhôm
A36: 28 | B36: RW-06 | C36: Ốp ngoài (lớp gỗ) | D36: Gỗ | E36: Ván gỗ 6 mm | F36: 2300 | G36: 276 | H36: 6 | I36: 1 | K36: =F36*G36*I36/1000000 -> 0.6348 | L36: Lớp gỗ dưới tấm nhôm
A37: 29 | B37: RW-07 | C37: Ốp ngoài cùng | D37: Nhôm | E37: Tấm nhôm 2 mm màu vàng | F37: 2300 | G37: 276 | H37: 2 | I37: 1 | K37: =F37*G37*I37/1000000 -> 0.6348 | L37: Mặt ngoài pod
A38: 30 | B38: RW-08 | C38: Ốp ngoài cùng | D38: Nhôm | E38: Tấm nhôm 2 mm màu vàng | F38: 2300 | G38: 1220 | H38: 2 | I38: 1 | K38: =F38*G38*I38/1000000 -> 2.806 | L38: Mặt ngoài pod
A39: BWL — Vách sau – trái
A40: 31 | B40: BWL-01 | C40: Khung | D40: Gỗ | E40: Thanh gỗ 40x40 | F40: 2169 | G40: 40 | H40: 40 | I40: 1 | J40: =F40*I40/1000 -> 2.169
A41: 32 | B41: BWL-02 | C41: Khung | D41: Gỗ | E41: Thanh gỗ 40x40 | F41: 2169 | G41: 40 | H41: 40 | I41: 1 | J41: =F41*I41/1000 -> 2.169 | L41: Có xẻ rãnh
...

Sheet Tổng hợp vật tư
A1: TỔNG HỢP VẬT TƯ – INDOOR POD V3
A3: Hao hụt cắt | B3: 0.05 | C3: Ô vàng là giả định (hao hụt, chiều dài cây, khổ tấm) – sửa theo nhà cung cấp, số cây/tấm tự tính lại.
A5: GỖ
A6: Quy cách | B6: Số lượng | C6: Tổng dài (m) | D6: Diện tích (m²) | E6: Cây dài (mm) / Khổ tấm (mm) | F6: Số cây / tấm cần | G6: Ghi chú
A7: Thanh gỗ 40x40 | B7: =SUMIFS(BOM!$I$5:$I$167,BOM!$D$5:$D$167,"Gỗ",BOM!$E$5:$E$167,A7) -> 32 | C7: =SUMIFS(BOM!$J$5:$J$167,BOM!$D$5:$D$167,"Gỗ",BOM!$E$5:$E$167,A7) -> 49.511 | E7: 3000 | F7: =ROUNDUP(C7*(1+$B$3)/(E7/1000),0) -> 18 | G7: Theo tổng chiều dài, chưa tối ưu sơ đồ cắt
A8: Ván gỗ 20 mm | B8: =SUMIFS(BOM!$I$5:$I$167,BOM!$D$5:$D$167,"Gỗ",BOM!$E$5:$E$167,A8) -> 1 | D8: =SUMIFS(BOM!$K$5:$K$167,BOM!$D$5:$D$167,"Gỗ",BOM!$E$5:$E$167,A8) -> 0.6 | E8: 1220x2440 | F8: =ROUNDUP(D8*(1+$B$3)/(VALUE(LEFT(E8,FIND("x",E8)-1))*VALUE(MID(E8,FIND("x",E8)+1,10))/1000000),0) -> 1 | G8: Theo diện tích, chưa tối ưu sơ đồ cắt
A9: Ván gỗ 6 mm | B9: =SUMIFS(BOM!$I$5:$I$167,BOM!$D$5:$D$167,"Gỗ",BOM!$E$5:$E$167,A9) -> 9 | D9: =SUMIFS(BOM!$K$5:$K$167,BOM!$D$5:$D$167,"Gỗ",BOM!$E$5:$E$167,A9) -> 16.262315 | E9: 1220x2440 | F9: =ROUNDUP(D9*(1+$B$3)/(VALUE(LEFT(E9,FIND("x",E9)-1))*VALUE(MID(E9,FIND("x",E9)+1,10))/1000000),0) -> 6 | G9: Theo diện tích, chưa tối ưu sơ đồ cắt
A10: Ván gỗ 9 mm | B10: =SUMIFS(BOM!$I$5:$I$167,BOM!$D$5:$D$167,"Gỗ",BOM!$E$5:$E$167,A10) -> 11 | D10: =SUMIFS(BOM!$K$5:$K$167,BOM!$D$5:$D$167,"Gỗ",BOM!$E$5:$E$167,A10) -> 18.600627 | E10: 1220x2440 | F10: =ROUNDUP(D10*(1+$B$3)/(VALUE(LEFT(E10,FIND("x",E10)-1))*VALUE(MID(E10,FIND("x",E10)+1,10))/1000000),0) -> 7 | G10: Theo diện tích, chưa tối ưu sơ đồ cắt
A12: THÉP
A13: Quy cách | B13: Số lượng | C13: Tổng dài (m) | D13: Diện tích (m²) | E13: Cây dài (mm) / Khổ tấm (mm) | F13: Số cây / tấm cần | G13: Ghi chú
A14: Hộp thép 100x50 | B14: =SUMIFS(BOM!$I$5:$I$167,BOM!$D$5:$D$167,"Thép",BOM!$E$5:$E$167,A14) -> 13 | C14: =SUMIFS(BOM!$J$5:$J$167,BOM!$D$5:$D$167,"Thép",BOM!$E$5:$E$167,A14) -> 8.3685 | E14: 6000 | F14: =ROUNDUP(C14*(1+$B$3)/(E14/1000),0) -> 2 | G14: Theo tổng chiều dài, chưa tối ưu sơ đồ cắt
A15: Hộp thép 16x16 | B15: =SUMIFS(BOM!$I$5:$I$167,BOM!$D$5:$D$167,"Thép",BOM!$E$5:$E$167,A15) -> 83 | C15: =SUMIFS(BOM!$J$5:$J$167,BOM!$D$5:$D$167,"Thép",BOM!$E$5:$E$167,A15) -> 39.3685 | E15: 6000 | F15: =ROUNDUP(C15*(1+$B$3)/(E15/1000),0) -> 7 | G15: Theo tổng chiều dài, chưa tối ưu sơ đồ cắt
A16: Hộp thép 20x20 | B16: =SUMIFS(BOM!$I$5:$I$167,BOM!$D$5:$D$167,"Thép",BOM!$E$5:$E$167,A16) -> 5 | C16: =SUMIFS(BOM!$J$5:$J$167,BOM!$D$5:$D$167,"Thép",BOM!$E$5:$E$167,A16) -> 0.6875 | E16: 6000 | F16: =ROUNDUP(C16*(1+$B$3)/(E16/1000),0) -> 1 | G16: Theo tổng chiều dài, chưa tối ưu sơ đồ cắt
A17: Hộp thép 60x20 | B17: =SUMIFS(BOM!$I$5:$I$167,BOM!$D$5:$D$167,"Thép",BOM!$E$5:$E$167,A17) -> 3 | C17: =SUMIFS(BOM!$J$5:$J$167,BOM!$D$5:$D$167,"Thép",BOM!$E$5:$E$167,A17) -> 1.9575 | E17: 6000 | F17: =ROUNDUP(C17*(1+$B$3)/(E17/1000),0) -> 1 | G17: Theo tổng chiều dài, chưa tối ưu sơ đồ cắt
A18: Hộp thép 60x30 | B18: =SUMIFS(BOM!$I$5:$I$167,BOM!$D$5:$D$167,"Thép",BOM!$E$5:$E$167,A18) -> 3 | C18: =SUMIFS(BOM!$J$5:$J$167,BOM!$D$5:$D$167,"Thép",BOM!$E$5:$E$167,A18) -> 7.2 | E18: 6000 | F18: =ROUNDUP(C18*(1+$B$3)/(E18/1000),0) -> 2 | G18: Theo tổng chiều dài, chưa tối ưu sơ đồ cắt
A19: Ống thép Ø100 | B19: =SUMIFS(BOM!$I$5:$I$167,BOM!$D$5:$D$167,"Thép",BOM!$E$5:$E$167,A19) -> 1 | C19: =SUMIFS(BOM!$J$5:$J$167,BOM!$D$5:$D$167,"Thép",BOM!$E$5:$E$167,A19) -> 0.797 | E19: 6000 | F19: =ROUNDUP(C19*(1+$B$3)/(E19/1000),0) -> 1 | G19: Theo tổng chiều dài, chưa tối ưu sơ đồ cắt
A20: Bản mã thép 3 mm | B20: =SUMIFS(BOM!$I$5:$I$167,BOM!$D$5:$D$167,"Thép",BOM!$E$5:$E$167,A20) -> 1
A21: Bản thép 3 mm | B21: =SUMIFS(BOM!$I$5:$I$167,BOM!$D$5:$D$167,"Thép",BOM!$E$5:$E$167,A21) -> 1
A22: Pát thép 2 mm | B22: =SUMIFS(BOM!$I$5:$I$167,BOM!$D$5:$D$167,"Thép",BOM!$E$5:$E$167,A22) -> 11
A23: Pát thép bẻ góc 3 mm | B23: =SUMIFS(BOM!$I$5:$I$167,BOM!$D$5:$D$167,"Thép",BOM!$E$5:$E$167,A23) -> 4
A25: NHÔM
A26: Quy cách | B26: Số lượng | C26: Tổng dài (m) | D26: Diện tích (m²) | E26: Cây dài (mm) / Khổ tấm (mm) | F26: Số cây / tấm cần | G26: Ghi chú
A27: Tấm nhôm 2 mm màu vàng | B27: =SUMIFS(BOM!$I$5:$I$167,BOM!$D$5:$D$167,"Nhôm",BOM!$E$5:$E$167,A27) -> 10 | D27: =SUMIFS(BOM!$K$5:$K$167,BOM!$D$5:$D$167,"Nhôm",BOM!$E$5:$E$167,A27) -> 17.602715 | E27: 1220x2440 | F27: =ROUNDUP(D27*(1+$B$3)/(VALUE(LEFT(E27,FIND("x",E27)-1))*VALUE(MID(E27,FIND("x",E27)+1,10))/1000000),0) -> 7 | G27: Theo diện tích, chưa tối ưu sơ đồ cắt
A28: Tấm nhôm 3 mm màu vàng | B28: =SUMIFS(BOM!$I$5:$I$167,BOM!$D$5:$D$167,"Nhôm",BOM!$E$5:$E$167,A28) -> 17 | D28: =SUMIFS(BOM!$K$5:$K$167,BOM!$D$5:$D$167,"Nhôm",BOM!$E$5:$E$167,A28) -> 8.0635287 | E28: 1220x2440 | F28: =ROUNDUP(D28*(1+$B$3)/(VALUE(LEFT(E28,FIND("x",E28)-1))*VALUE(MID(E28,FIND("x",E28)+1,10))/1000000),0) -> 3 | G28: Theo diện tích, chưa tối ưu sơ đồ cắt
A30: KÍNH
A31: Quy cách | B31: Số lượng | C31: Tổng dài (m) | D31: Diện tích (m²) | E31: Cây dài (mm) / Khổ tấm (mm) | F31: Số cây / tấm cần | G31: Ghi chú
A32: Kính xám khói 10 mm | B32: =SUMIFS(BOM!$I$5:$I$167,BOM!$D$5:$D$167,"Kính",BOM!$E$5:$E$167,A32) -> 2 | D32: =SUMIFS(BOM!$K$5:$K$167,BOM!$D$5:$D$167,"Kính",BOM!$E$5:$E$167,A32) -> 3.911764 | G32: Đặt cắt theo kích thước: cửa 2011x1176, vách 2139x724
A34: VÍT & TÁN CẤY BẮT VÁCH
A35: Quy cách | B35: Số lượng | F35: Mã NCC / link | G35: Ghi chú
A36: Vít M8x60 | B36: =SUMIFS(BOM!$I$5:$I$167,BOM!$E$5:$E$167,A36) -> 18 | G36: 8 con: 2 góc sau (vách sau trái/phải ↔ vách trái/phải), 4 con mỗi góc; 10 con: trần ↔ vách (vách trái 3, vách phải 3, vách sau trái 2, vách sau phải 2)
A37: Vít M8x40 | B37: =SUMIFS(BOM!$I$5:$I$167,BOM!$E$5:$E$167,A37) -> 8 | G37: Vách sau giữa ↔ vách sau trái/phải, 4 con mỗi bên
A38: Tán cấy M8x20 | B38: =SUMIFS(BOM!$I$5:$I$167,BOM!$E$5:$E$167,A38) -> 26 | G38: Cấy vào khung gỗ, 1 con cho mỗi vít M8
A40: LINH KIỆN MUA
A41: Linh kiện | B41: Số lượng | F41: Mã NCC / link | G41: Ghi chú
A42: Chân tăng chỉnh D50 ren M12 | B42: =SUMIFS(BOM!$I$5:$I$167,BOM!$E$5:$E$167,A42) -> 6
A43: Quạt thông gió 200x200x60 | B43: =SUMIFS(BOM!$I$5:$I$167,BOM!$E$5:$E$167,A43) -> 4 | G43: 2 cụm, mỗi cụm 2 quạt
A44: Đèn ốp trần vuông 170x170 | B44: =SUMIFS(BOM!$I$5:$I$167,BOM!$E$5:$E$167,A44) -> 2
A45: Công tắc (mặt 86x86) | B45: =SUMIFS(BOM!$I$5:$I$167,BOM!$E$5:$E$167,A45) -> 1
A46: Ổ cắm điện (mặt 86x86) | B46: =SUMIFS(BOM!$I$5:$I$167,BOM!$E$5:$E$167,A46) -> 1
A47: Ổ mạng LAN (mặt 86x86) | B47: =SUMIFS(BOM!$I$5:$I$167,BOM!$E$5:$E$167,A47) -> 1
...
